Workbook

Sheet 设施故障率
A1: 序号 | B1: 设施类别 | C1: 设施故障停电率 （次/百千米百台·年） | D1: 平均故障 修复时间 （h） | E1: 平均故障 定位隔离时间 (h) | F1: 平均故障 停电联络开关切换时间 (h) | G1: 平均故障段上游 恢复供电操作时间 (h) | H1: 平均预安排 停电隔离时间 (h) | I1: 平均预安排 停电联络开关切换时间 (h) | J1: 平均预安排 停电线段上游恢复供电操作时间 (h) | K1: 系统预安排 停电率 (次/百千米·年) | L1: 平均预安排 停运持续时间 (h)
A2: 1 | B2: 架空线 | C2: 0.3 | D2: 2 | K2: 6 | L2: 7
A3: 2 | B3: 电缆 | C3: 0.1 | D3: 5 | K3: 6 | L3: 7
A4: 3 | B4: 断路器 | C4: 0.25 | D4: 3 | E4: 1 | F4: 0.5 | G4: 0.3 | H4: 0.1 | I4: 0.1 | J4: 0.1
A5: 4 | B5: 负荷开关 | C5: 0.2 | D5: 2.5 | E5: 1 | F5: 0.5 | G5: 0.3 | H5: 0.1 | I5: 0.1 | J5: 0.1
A6: 5 | B6: 隔离开关 | C6: 0.25 | D6: 2.5 | E6: 1 | F6: 0.5 | G6: 0.3 | H6: 0.1 | I6: 0.1 | J6: 0.1
A7: 6 | B7: 熔断器 | C7: 0.2 | D7: 2 | E7: 1 | F7: 0.5 | G7: 0.3 | H7: 0.1 | I7: 0.1 | J7: 0.1
A8: 7 | B8: 变压器 | C8: 0.35 | D8: 4

Sheet 算例图

Sheet 数据1
A1: 设施 | C1: 长度（km） | D1: 设施类别 | E1: 设施故障停电率 （次/百千米百台·年） | F1: 设施故障停电率 （次/年） | G1: 平均故障修复时间（h） | H1: 用户数（户） | I1: 负荷容量（kW） | J1: 系统预安排 停电率 (次/百千米·年) | K1: 平均预安排停运持续时间(h) | L1: 预安排停电次数 (次/年) | M1: 预安排停电时间 (h)
A2: 供电干线 | B2: 0—1 | C2: 0.5 | D2: 架空线 | E2: =VLOOKUP(D2,设施故障率!B:D,2,FALSE) -> 0.3 | F2: =C2/100*E2 -> 0.0015 | G2: =VLOOKUP(D2,设施故障率!B:D,3,FALSE) -> 2 | J2: =VLOOKUP(D2,设施故障率!B:M,10,FALSE) -> 6 | K2: =VLOOKUP(D2,设施故障率!B:M,11,FALSE) -> 7 | L2: =C2/100*J2 -> 0.03 | M2: =K2*L2 -> 0.21
B3: 1—2 | C3: 2 | D3: 电缆 | E3: =VLOOKUP(D3,设施故障率!B:D,2,FALSE) -> 0.1 | F3: =C3/100*E3 -> 0.002 | G3: =VLOOKUP(D3,设施故障率!B:D,3,FALSE) -> 5 | J3: =VLOOKUP(D3,设施故障率!B:M,10,FALSE) -> 6 | K3: =VLOOKUP(D3,设施故障率!B:M,11,FALSE) -> 7 | L3: =C3/100*J3 -> 0.12 | M3: =K3*L3 -> 0.84
B4: 2—3 | C4: 3 | D4: 电缆 | E4: =VLOOKUP(D4,设施故障率!B:D,2,FALSE) -> 0.1 | F4: =C4/100*E4 -> 0.003 | G4: =VLOOKUP(D4,设施故障率!B:D,3,FALSE) -> 5 | J4: =VLOOKUP(D4,设施故障率!B:M,10,FALSE) -> 6 | K4: =VLOOKUP(D4,设施故障率!B:M,11,FALSE) -> 7 | L4: =C4/100*J4 -> 0.18 | M4: =K4*L4 -> 1.26
B5: 3—4 | C5: 3 | D5: 架空线 | E5: =VLOOKUP(D5,设施故障率!B:D,2,FALSE) -> 0.3 | F5: =C5/100*E5 -> 0.009 | G5: =VLOOKUP(D5,设施故障率!B:D,3,FALSE) -> 2 | J5: =VLOOKUP(D5,设施故障率!B:M,10,FALSE) -> 6 | K5: =VLOOKUP(D5,设施故障率!B:M,11,FALSE) -> 7 | L5: =C5/100*J5 -> 0.18 | M5: =K5*L5 -> 1.26
B6: 4—5 | C6: 1 | D6: 架空线 | E6: =VLOOKUP(D6,设施故障率!B:D,2,FALSE) -> 0.3 | F6: =C6/100*E6 -> 0.003 | G6: =VLOOKUP(D6,设施故障率!B:D,3,FALSE) -> 2 | J6: =VLOOKUP(D6,设施故障率!B:M,10,FALSE) -> 6 | K6: =VLOOKUP(D6,设施故障率!B:M,11,FALSE) -> 7 | L6: =C6/100*J6 -> 0.06 | M6: =K6*L6 -> 0.42
B7: 5—6 | C7: 2 | D7: 架空线 | E7: =VLOOKUP(D7,设施故障率!B:D,2,FALSE) -> 0.3 | F7: =C7/100*E7 -> 0.006 | G7: =VLOOKUP(D7,设施故障率!B:D,3,FALSE) -> 2 | J7: =VLOOKUP(D7,设施故障率!B:M,10,FALSE) -> 6 | K7: =VLOOKUP(D7,设施故障率!B:M,11,FALSE) -> 7 | L7: =C7/100*J7 -> 0.12 | M7: =K7*L7 -> 0.84
B8: 6—7 | C8: 2 | D8: 架空线 | E8: =VLOOKUP(D8,设施故障率!B:D,2,FALSE) -> 0.3 | F8: =C8/100*E8 -> 0.006 | G8: =VLOOKUP(D8,设施故障率!B:D,3,FALSE) -> 2 | J8: =VLOOKUP(D8,设施故障率!B:M,10,FALSE) -> 6 | K8: =VLOOKUP(D8,设施故障率!B:M,11,FALSE) -> 7 | L8: =C8/100*J8 -> 0.12 | M8: =K8*L8 -> 0.84
B9: 5—8 | C9: 1 | D9: 架空线 | E9: =VLOOKUP(D9,设施故障率!B:D,2,FALSE) -> 0.3 | F9: =C9/100*E9 -> 0.003 | G9: =VLOOKUP(D9,设施故障率!B:D,3,FALSE) -> 2 | J9: =VLOOKUP(D9,设施故障率!B:M,10,FALSE) -> 6 | K9: =VLOOKUP(D9,设施故障率!B:M,11,FALSE) -> 7 | L9: =C9/100*J9 -> 0.06 | M9: =K9*L9 -> 0.42
A10: 分支线 | B10: 2—a | C10: 1 | D10: 电缆 | E10: =VLOOKUP(D10,设施故障率!B:D,2,FALSE) -> 0.1 | F10: =C10/100*E10 -> 0.001 | G10: =VLOOKUP(D10,设施故障率!B:D,3,FALSE) -> 5 | J10: =VLOOKUP(D10,设施故障率!B:M,10,FALSE) -> 6 | K10: =VLOOKUP(D10,设施故障率!B:M,11,FALSE) -> 7 | L10: =C10/100*J10 -> 0.06 | M10: =K10*L10 -> 0.42
B11: 4—b | C11: 1.5 | D11: 架空线 | E11: =VLOOKUP(D11,设施故障率!B:D,2,FALSE) -> 0.3 | F11: =C11/100*E11 -> 0.0045 | G11: =VLOOKUP(D11,设施故障率!B:D,3,FALSE) -> 2 | J11: =VLOOKUP(D11,设施故障率!B:M,10,FALSE) -> 6 | K11: =VLOOKUP(D11,设施故障率!B:M,11,FALSE) -> 7 | L11: =C11/100*J11 -> 0.09 | M11: =K11*L11 -> 0.63
B12: 8—c | C12: 1.5 | D12: 架空线 | E12: =VLOOKUP(D12,设施故障率!B:D,2,FALSE) -> 0.3 | F12: =C12/100*E12 -> 0.0045 | G12: =VLOOKUP(D12,设施故障率!B:D,3,FALSE) -> 2 | J12: =VLOOKUP(D12,设施故障率!B:M,10,FALSE) -> 6 | K12: =VLOOKUP(D12,设施故障率!B:M,11,FALSE) -> 7 | L12: =C12/100*J12 -> 0.09 | M12: =K12*L12 -> 0.63
B13: 8—d | C13: 0.5 | D13: 架空线 | E13: =VLOOKUP(D13,设施故障率!B:D,2,FALSE) -> 0.3 | F13: =C13/100*E13 -> 0.0015 | G13: =VLOOKUP(D13,设施故障率!B:D,3,FALSE) -> 2 | J13: =VLOOKUP(D13,设施故障率!B:M,10,FALSE) -> 6 | K13: =VLOOKUP(D13,设施故障率!B:M,11,FALSE) -> 7 | L13: =C13/100*J13 -> 0.03 | M13: =K13*L13 -> 0.21
B14: 6—e | C14: 1 | D14: 架空线 | E14: =VLOOKUP(D14,设施故障率!B:D,2,FALSE) -> 0.3 | F14: =C14/100*E14 -> 0.003 | G14: =VLOOKUP(D14,设施故障率!B:D,3,FALSE) -> 2 | J14: =VLOOKUP(D14,设施故障率!B:M,10,FALSE) -> 6 | K14: =VLOOKUP(D14,设施故障率!B:M,11,FALSE) -> 7 | L14: =C14/100*J14 -> 0.06 | M14: =K14*L14 -> 0.42
A15: 设备 | B15: CB4 | C15: 1 | D15: 断路器 | E15: =VLOOKUP(D15,设施故障率!B:D,2,FALSE) -> 0.25 | F15: =C15/100*E15 -> 0.0025 | G15: =VLOOKUP(D15,设施故障率!B:D,3,FALSE) -> 3 | J15: =VLOOKUP(D15,设施故障率!B:M,10,FALSE) -> 0 | K15: =VLOOKUP(D15,设施故障率!B:M,11,FALSE) -> 0 | L15: =C15/100*J15 -> 0 | M15: =K15*L15 -> 0
B16: CB1 | C16: 1 | D16: 断路器 | E16: =VLOOKUP(D16,设施故障率!B:D,2,FALSE) -> 0.25 | F16: =C16/100*E16 -> 0.0025 | G16: =VLOOKUP(D16,设施故障率!B:D,3,FALSE) -> 3 | J16: =VLOOKUP(D16,设施故障率!B:M,10,FALSE) -> 0 | K16: =VLOOKUP(D16,设施故障率!B:M,11,FALSE) -> 0 | L16: =C16/100*J16 -> 0 | M16: =K16*L16 -> 0
B17: CB2 | C17: 1 | D17: 断路器 | E17: =VLOOKUP(D17,设施故障率!B:D,2,FALSE) -> 0.25 | F17: =C17/100*E17 -> 0.0025 | G17: =VLOOKUP(D17,设施故障率!B:D,3,FALSE) -> 3 | J17: =VLOOKUP(D17,设施故障率!B:M,10,FALSE) -> 0 | K17: =VLOOKUP(D17,设施故障率!B:M,11,FALSE) -> 0 | L17: =C17/100*J17 -> 0 | M17: =K17*L17 -> 0
B18: CB3 | C18: 1 | D18: 断路器 | E18: =VLOOKUP(D18,设施故障率!B:D,2,FALSE) -> 0.25 | F18: =C18/100*E18 -> 0.0025 | G18: =VLOOKUP(D18,设施故障率!B:D,3,FALSE) -> 3 | J18: =VLOOKUP(D18,设施故障率!B:M,10,FALSE) -> 0 | K18: =VLOOKUP(D18,设施故障率!B:M,11,FALSE) -> 0 | L18: =C18/100*J18 -> 0 | M18: =K18*L18 -> 0
B19: S1 | C19: 1 | D19: 隔离开关 | E19: =VLOOKUP(D19,设施故障率!B:D,2,FALSE) -> 0.25 | F19: =C19/100*E19 -> 0.0025 | G19: =VLOOKUP(D19,设施故障率!B:D,3,FALSE) -> 2.5 | J19: =VLOOKUP(D19,设施故障率!B:M,10,FALSE) -> 0 | K19: =VLOOKUP(D19,设施故障率!B:M,11,FALSE) -> 0 | L19: =C19/100*J19 -> 0 | M19: =K19*L19 -> 0
B20: S2 | C20: 1 | D20: 隔离开关 | E20: =VLOOKUP(D20,设施故障率!B:D,2,FALSE) -> 0.25 | F20: =C20/100*E20 -> 0.0025 | G20: =VLOOKUP(D20,设施故障率!B:D,3,FALSE) -> 2.5 | J20: =VLOOKUP(D20,设施故障率!B:M,10,FALSE) -> 0 | K20: =VLOOKUP(D20,设施故障率!B:M,11,FALSE) -> 0 | L20: =C20/100*J20 -> 0 | M20: =K20*L20 -> 0
B21: LS1 | C21: 1 | D21: 负荷开关 | E21: =VLOOKUP(D21,设施故障率!B:D,2,FALSE) -> 0.2 | F21: =C21/100*E21 -> 0.002 | G21: =VLOOKUP(D21,设施故障率!B:D,3,FALSE) -> 2.5 | J21: =VLOOKUP(D21,设施故障率!B:M,10,FALSE) -> 0 | K21: =VLOOKUP(D21,设施故障率!B:M,11,FALSE) -> 0 | L21: =C21/100*J21 -> 0 | M21: =K21*L21 -> 0
B22: LS2 | C22: 1 | D22: 负荷开关 | E22: =VLOOKUP(D22,设施故障率!B:D,2,FALSE) -> 0.2 | F22: =C22/100*E22 -> 0.002 | G22: =VLOOKUP(D22,设施故障率!B:D,3,FALSE) -> 2.5 | J22: =VLOOKUP(D22,设施故障率!B:M,10,FALSE) -> 0 | K22: =VLOOKUP(D22,设施故障率!B:M,11,FALSE) -> 0 | L22: =C22/100*J22 -> 0 | M22: =K22*L22 -> 0
B23: F5 | C23: 1 | D23: 熔断器 | E23: =VLOOKUP(D23,设施故障率!B:D,2,FALSE) -> 0.2 | F23: =C23/100*E23 -> 0.002 | G23: =VLOOKUP(D23,设施故障率!B:D,3,FALSE) -> 2 | J23: =VLOOKUP(D23,设施故障率!B:M,10,FALSE) -> 0 | K23: =VLOOKUP(D23,设施故障率!B:M,11,FALSE) -> 0 | L23: =C23/100*J23 -> 0 | M23: =K23*L23 -> 0
B24: Ta | C24: 1 | D24: 变压器 | E24: =VLOOKUP(D24,设施故障率!B:D,2,FALSE) -> 0.35 | F24: =C24/100*E24 -> 0.0035 | G24: =VLOOKUP(D24,设施故障率!B:D,3,FALSE) -> 4 | H24: 1 | I24: 800 | J24: =VLOOKUP(D24,设施故障率!B:M,10,FALSE) -> 0 | K24: =VLOOKUP(D24,设施故障率!B:M,11,FALSE) -> 0 | L24: =C24/100*J24 -> 0 | M24: =K24*L24 -> 0
B25: Tb | C25: 1 | D25: 变压器 | E25: =VLOOKUP(D25,设施故障率!B:D,2,FALSE) -> 0.35 | F25: =C25/100*E25 -> 0.0035 | G25: =VLOOKUP(D25,设施故障率!B:D,3,FALSE) -> 4 | H25: 1 | I25: 200 | J25: =VLOOKUP(D25,设施故障率!B:M,10,FALSE) -> 0 | K25: =VLOOKUP(D25,设施故障率!B:M,11,FALSE) -> 0 | L25: =C25/100*J25 -> 0 | M25: =K25*L25 -> 0
B26: Tc | C26: 1 | D26: 变压器 | E26: =VLOOKUP(D26,设施故障率!B:D,2,FALSE) -> 0.35 | F26: =C26/100*E26 -> 0.0035 | G26: =VLOOKUP(D26,设施故障率!B:D,3,FALSE) -> 4 | H26: 1 | I26: 50 | J26: =VLOOKUP(D26,设施故障率!B:M,10,FALSE) -> 0 | K26: =VLOOKUP(D26,设施故障率!B:M,11,FALSE) -> 0 | L26: =C26/100*J26 -> 0 | M26: =K26*L26 -> 0
B27: Td | C27: 1 | D27: 变压器 | E27: =VLOOKUP(D27,设施故障率!B:D,2,FALSE) -> 0.35 | F27: =C27/100*E27 -> 0.0035 | G27: =VLOOKUP(D27,设施故障率!B:D,3,FALSE) -> 4 | H27: 1 | I27: 100 | J27: =VLOOKUP(D27,设施故障率!B:M,10,FALSE) -> 0 | K27: =VLOOKUP(D27,设施故障率!B:M,11,FALSE) -> 0 | L27: =C27/100*J27 -> 0 | M27: =K27*L27 -> 0
B28: Te | C28: 1 | D28: 变压器 | E28: =VLOOKUP(D28,设施故障率!B:D,2,FALSE) -> 0.35 | F28: =C28/100*E28 -> 0.0035 | G28: =VLOOKUP(D28,设施故障率!B:D,3,FALSE) -> 4 | H28: 1 | I28: 315 | J28: =VLOOKUP(D28,设施故障率!B:M,10,FALSE) -> 0 | K28: =VLOOKUP(D28,设施故障率!B:M,11,FALSE) -> 0 | L28: =C28/100*J28 -> 0 | M28: =K28*L28 -> 0
B29: Fa | C29: 1 | D29: 熔断器 | E29: =VLOOKUP(D29,设施故障率!B:D,2,FALSE) -> 0.2 | F29: =C29/100*E29 -> 0.002 | G29: =VLOOKUP(D29,设施故障率!B:D,3,FALSE) -> 2 | J29: =VLOOKUP(D29,设施故障率!B:M,10,FALSE) -> 0 | K29: =VLOOKUP(D29,设施故障率!B:M,11,FALSE) -> 0 | L29: =C29/100*J29 -> 0 | M29: =K29*L29 -> 0
B30: Fb | C30: 1 | D30: 熔断器 | E30: =VLOOKUP(D30,设施故障率!B:D,2,FALSE) -> 0.2 | F30: =C30/100*E30 -> 0.002 | G30: =VLOOKUP(D30,设施故障率!B:D,3,FALSE) -> 2 | J30: =VLOOKUP(D30,设施故障率!B:M,10,FALSE) -> 0 | K30: =VLOOKUP(D30,设施故障率!B:M,11,FALSE) -> 0 | L30: =C30/100*J30 -> 0 | M30: =K30*L30 -> 0
B31: Fc | C31: 1 | D31: 熔断器 | E31: =VLOOKUP(D31,设施故障率!B:D,2,FALSE) -> 0.2 | F31: =C31/100*E31 -> 0.002 | G31: =VLOOKUP(D31,设施故障率!B:D,3,FALSE) -> 2 | J31: =VLOOKUP(D31,设施故障率!B:M,10,FALSE) -> 0 | K31: =VLOOKUP(D31,设施故障率!B:M,11,FALSE) -> 0 | L31: =C31/100*J31 -> 0 | M31: =K31*L31 -> 0
B32: Fd | C32: 1 | D32: 熔断器 | E32: =VLOOKUP(D32,设施故障率!B:D,2,FALSE) -> 0.2 | F32: =C32/100*E32 -> 0.002 | G32: =VLOOKUP(D32,设施故障率!B:D,3,FALSE) -> 2 | J32: =VLOOKUP(D32,设施故障率!B:M,10,FALSE) -> 0 | K32: =VLOOKUP(D32,设施故障率!B:M,11,FALSE) -> 0 | L32: =C32/100*J32 -> 0 | M32: =K32*L32 -> 0
B33: Fe | C33: 1 | D33: 熔断器 | E33: =VLOOKUP(D33,设施故障率!B:D,2,FALSE) -> 0.2 | F33: =C33/100*E33 -> 0.002 | G33: =VLOOKUP(D33,设施故障率!B:D,3,FALSE) -> 2 | J33: =VLOOKUP(D33,设施故障率!B:M,10,FALSE) -> 0 | K33: =VLOOKUP(D33,设施故障率!B:M,11,FALSE) -> 0 | L33: =C33/100*J33 -> 0 | M33: =K33*L33 -> 0
B34: S3 | C34: 1 | D34: 隔离开关 | E34: =VLOOKUP(D34,设施故障率!B:D,2,FALSE) -> 0.25 | F34: =C34/100*E34 -> 0.0025 | G34: =VLOOKUP(D34,设施故障率!B:D,3,FALSE) -> 2.5 | J34: =VLOOKUP(D34,设施故障率!B:M,10,FALSE) -> 0 | K34: =VLOOKUP(D34,设施故障率!B:M,11,FALSE) -> 0 | L34: =C34/100*J34 -> 0 | M34: =K34*L34 -> 0

Sheet 数据2
A1: 设施类别 | B1: 平均故障定位隔离时间 (h) | C1: 平均故障停电联络开关切换时间 (h) | D1: 平均故障段上游恢复供电操作时间 (h)
A2: 开关设备 | B2: 1 | C2: 0.5 | D2: 0.3
A3: 设施类别 | B3: 平均预安排停电隔离时间 (h) | C3: 平均预安排停电联络开关切换时间 (h) | D3: 平均预安排停电线段上游恢复供电操作时间 (h)
A4: 开关设备 | B4: 0.1 | C4: 0.1 | D4: 0.1
A5: 设施类别 | B5: 预安排停电率 (次/百公里年) | C5: 平均预安排停运持续时间 (h) | D5: ---
A6: 架空（电缆）线路 | B6: 6 | C6: 7 | D6: ---

Sheet 故障后果模式分析表
A1: 表C.3 故障后果模式分析表
B3: 设施 | D3: 设施类别 | E3: 负荷点a | H3: 负荷点b | K3: 负荷点c | N3: 负荷点d | Q3: 负荷点e
E4: λLP | F4: rLP | G4: uLP | H4: λLP | I4: rLP | J4: uLP | K4: λLP | L4: rLP | M4: uLP | N4: λLP | O4: rLP | P4: uLP | Q4: λLP | R4: rLP | S4: uLP
E5: 次/年 | F5: h/次 | G5: h/年 | H5: 次/年 | I5: h/次 | J5: h/年 | K5: 次/年 | L5: h/次 | M5: h/年 | N5: 次/年 | O5: h/次 | P5: h/年 | Q5: 次/年 | R5: h/次 | S5: h/年
B6: 干线设施故障 | C6: CB4 | D6: =VLOOKUP(C6,数据1!B:I,3,FALSE) -> 断路器 | E6: =IF(F6>0,VLOOKUP($C6,数据1!$B:$N,5,FALSE),0) -> 0.0025 | F6: 1.5 | G6: =E6*F6 -> 0.00375 | H6: =IF(I6>0,VLOOKUP($C6,数据1!$B:$N,5,FALSE),0) -> 0.0025 | I6: 1.5 | J6: =H6*I6 -> 0.00375 | K6: =IF(L6>0,VLOOKUP($C6,数据1!$B:$N,5,FALSE),0) -> 0.0025 | L6: 1.5 | M6: =K6*L6 -> 0.00375 | N6: =IF(O6>0,VLOOKUP($C6,数据1!$B:$N,5,FALSE),0) -> 0.0025 | O6: 1.5 | P6: =N6*O6 -> 0.00375 | Q6: =IF(R6>0,VLOOKUP($C6,数据1!$B:$N,5,FALSE),0) -> 0.0025 | R6: 1.5 | S6: =Q6*R6 -> 0.00375
C7: 0—1 | D7: =VLOOKUP(C7,数据1!B:I,3,FALSE) -> 架空线 | E7: =IF(F7>0,VLOOKUP($C7,数据1!$B:$N,5,FALSE),0) -> 0.0015 | F7: 1.5 | G7: =E7*F7 -> 0.00225 | H7: =IF(I7>0,VLOOKUP($C7,数据1!$B:$N,5,FALSE),0) -> 0.0015 | I7: 1.5 | J7: =H7*I7 -> 0.00225 | K7: =IF(L7>0,VLOOKUP($C7,数据1!$B:$N,5,FALSE),0) -> 0.0015 | L7: 1.5 | M7: =K7*L7 -> 0.00225 | N7: =IF(O7>0,VLOOKUP($C7,数据1!$B:$N,5,FALSE),0) -> 0.0015 | O7: 1.5 | P7: =N7*O7 -> 0.00225 | Q7: =IF(R7>0,VLOOKUP($C7,数据1!$B:$N,5,FALSE),0) -> 0.0015 | R7: 1.5 | S7: =Q7*R7 -> 0.00225
C8: 1—2 | D8: =VLOOKUP(C8,数据1!B:I,3,FALSE) -> 电缆 | E8: =IF(F8>0,VLOOKUP($C8,数据1!$B:$N,5,FALSE),0) -> 0.002 | F8: 1.5 | G8: =E8*F8 -> 0.003 | H8: =IF(I8>0,VLOOKUP($C8,数据1!$B:$N,5,FALSE),0) -> 0.002 | I8: 1.5 | J8: =H8*I8 -> 0.003 | K8: =IF(L8>0,VLOOKUP($C8,数据1!$B:$N,5,FALSE),0) -> 0.002 | L8: 1.5 | M8: =K8*L8 -> 0.003 | N8: =IF(O8>0,VLOOKUP($C8,数据1!$B:$N,5,FALSE),0) -> 0.002 | O8: 1.5 | P8: =N8*O8 -> 0.003 | Q8: =IF(R8>0,VLOOKUP($C8,数据1!$B:$N,5,FALSE),0) -> 0.002 | R8: 1.5 | S8: =Q8*R8 -> 0.003
C9: CB1 | D9: =VLOOKUP(C9,数据1!B:I,3,FALSE) -> 断路器 | E9: =IF(F9>0,VLOOKUP($C9,数据1!$B:$N,5,FALSE),0) -> 0.0025 | F9: 1.5 | G9: =E9*F9 -> 0.00375 | H9: =IF(I9>0,VLOOKUP($C9,数据1!$B:$N,5,FALSE),0) -> 0.0025 | I9: 1.5 | J9: =H9*I9 -> 0.00375 | K9: =IF(L9>0,VLOOKUP($C9,数据1!$B:$N,5,FALSE),0) -> 0.0025 | L9: 1.5 | M9: =K9*L9 -> 0.00375 | N9: =IF(O9>0,VLOOKUP($C9,数据1!$B:$N,5,FALSE),0) -> 0.0025 | O9: 1.5 | P9: =N9*O9 -> 0.00375 | Q9: =IF(R9>0,VLOOKUP($C9,数据1!$B:$N,5,FALSE),0) -> 0.0025 | R9: 1.5 | S9: =Q9*R9 -> 0.00375
C10: CB3 | D10: =VLOOKUP(C10,数据1!B:I,3,FALSE) -> 断路器 | E10: =IF(F10>0,VLOOKUP($C10,数据1!$B:$N,5,FALSE),0) -> 0.0025 | F10: 1.3 | G10: =E10*F10 -> 0.00325 | H10: =IF(I10>0,VLOOKUP($C10,数据1!$B:$N,5,FALSE),0) -> 0.0025 | I10: 1.5 | J10: =H10*I10 -> 0.00375 | K10: =IF(L10>0,VLOOKUP($C10,数据1!$B:$N,5,FALSE),0) -> 0.0025 | L10: 1.5 | M10: =K10*L10 -> 0.00375 | N10: =IF(O10>0,VLOOKUP($C10,数据1!$B:$N,5,FALSE),0) -> 0.0025 | O10: 1.5 | P10: =N10*O10 -> 0.00375 | Q10: =IF(R10>0,VLOOKUP($C10,数据1!$B:$N,5,FALSE),0) -> 0.0025 | R10: 1.5 | S10: =Q10*R10 -> 0.00375
C11: 2—3 | D11: =VLOOKUP(C11,数据1!B:I,3,FALSE) -> 电缆 | E11: =IF(F11>0,VLOOKUP($C11,数据1!$B:$N,5,FALSE),0) -> 0 | F11: 0 | G11: =E11*F11 -> 0 | H11: =IF(I11>0,VLOOKUP($C11,数据1!$B:$N,5,FALSE),0) -> 0.003 | I11: 1.5 | J11: =H11*I11 -> 0.0045 | K11: =IF(L11>0,VLOOKUP($C11,数据1!$B:$N,5,FALSE),0) -> 0.003 | L11: 1.5 | M11: =K11*L11 -> 0.0045 | N11: =IF(O11>0,VLOOKUP($C11,数据1!$B:$N,5,FALSE),0) -> 0.003 | O11: 1.5 | P11: =N11*O11 -> 0.0045 | Q11: =IF(R11>0,VLOOKUP($C11,数据1!$B:$N,5,FALSE),0) -> 0.003 | R11: 1.5 | S11: =Q11*R11 -> 0.0045
C12: S1 | D12: =VLOOKUP(C12,数据1!B:I,3,FALSE) -> 隔离开关 | E12: =IF(F12>0,VLOOKUP($C12,数据1!$B:$N,5,FALSE),0) -> 0 | F12: 0 | G12: =E12*F12 -> 0 | H12: =IF(I12>0,VLOOKUP($C12,数据1!$B:$N,5,FALSE),0) -> 0.0025 | I12: 2.5 | J12: =H12*I12 -> 0.00625 | K12: =IF(L12>0,VLOOKUP($C12,数据1!$B:$N,5,FALSE),0) -> 0.0025 | L12: 1.5 | M12: =K12*L12 -> 0.00375 | N12: =IF(O12>0,VLOOKUP($C12,数据1!$B:$N,5,FALSE),0) -> 0.0025 | O12: 1.5 | P12: =N12*O12 -> 0.00375 | Q12: =IF(R12>0,VLOOKUP($C12,数据1!$B:$N,5,FALSE),0) -> 0.0025 | R12: 1.5 | S12: =Q12*R12 -> 0.00375
C13: 3—4 | D13: =VLOOKUP(C13,数据1!B:I,3,FALSE) -> 架空线 | E13: =IF(F13>0,VLOOKUP($C13,数据1!$B:$N,5,FALSE),0) -> 0 | F13: 0 | G13: =E13*F13 -> 0 | H13: =IF(I13>0,VLOOKUP($C13,数据1!$B:$N,5,FALSE),0) -> 0.009 | I13: 2 | J13: =H13*I13 -> 0.018 | K13: =IF(L13>0,VLOOKUP($C13,数据1!$B:$N,5,FALSE),0) -> 0.009 | L13: 1.5 | M13: =K13*L13 -> 0.0135 | N13: =IF(O13>0,VLOOKUP($C13,数据1!$B:$N,5,FALSE),0) -> 0.009 | O13: 1.5 | P13: =N13*O13 -> 0.0135 | Q13: =IF(R13>0,VLOOKUP($C13,数据1!$B:$N,5,FALSE),0) -> 0.009 | R13: 1.5 | S13: =Q13*R13 -> 0.0135
C14: LS1 | D14: =VLOOKUP(C14,数据1!B:I,3,FALSE) -> 负荷开关 | E14: =IF(F14>0,VLOOKUP($C14,数据1!$B:$N,5,FALSE),0) -> 0 | F14: 0 | G14: =E14*F14 -> 0 | H14: =IF(I14>0,VLOOKUP($C14,数据1!$B:$N,5,FALSE),0) -> 0.002 | I14: 1.3 | J14: =H14*I14 -> 0.0026 | K14: =IF(L14>0,VLOOKUP($C14,数据1!$B:$N,5,FALSE),0) -> 0.002 | L14: 1.5 | M14: =K14*L14 -> 0.003 | N14: =IF(O14>0,VLOOKUP($C14,数据1!$B:$N,5,FALSE),0) -> 0.002 | O14: 1.5 | P14: =N14*O14 -> 0.003 | Q14: =IF(R14>0,VLOOKUP($C14,数据1!$B:$N,5,FALSE),0) -> 0.002 | R14: 1.5 | S14: =Q14*R14 -> 0.003
C15: 4—5 | D15: =VLOOKUP(C15,数据1!B:I,3,FALSE) -> 架空线 | E15: =IF(F15>0,VLOOKUP($C15,数据1!$B:$N,5,FALSE),0) -> 0 | F15: 0 | G15: =E15*F15 -> 0 | H15: =IF(I15>0,VLOOKUP($C15,数据1!$B:$N,5,FALSE),0) -> 0.003 | I15: 1.3 | J15: =H15*I15 -> 0.0039 | K15: =IF(L15>0,VLOOKUP($C15,数据1!$B:$N,5,FALSE),0) -> 0.003 | L15: 2 | M15: =K15*L15 -> 0.006 | N15: =IF(O15>0,VLOOKUP($C15,数据1!$B:$N,5,FALSE),0) -> 0.003 | O15: 2 | P15: =N15*O15 -> 0.006 | Q15: =IF(R15>0,VLOOKUP($C15,数据1!$B:$N,5,FALSE),0) -> 0.003 | R15: 2 | S15: =Q15*R15 -> 0.006
C16: 5—6 | D16: =VLOOKUP(C16,数据1!B:I,3,FALSE) -> 架空线 | E16: =IF(F16>0,VLOOKUP($C16,数据1!$B:$N,5,FALSE),0) -> 0 | F16: 0 | G16: =E16*F16 -> 0 | H16: =IF(I16>0,VLOOKUP($C16,数据1!$B:$N,5,FALSE),0) -> 0.006 | I16: 1.3 | J16: =H16*I16 -> 0.0078 | K16: =IF(L16>0,VLOOKUP($C16,数据1!$B:$N,5,FALSE),0) -> 0.006 | L16: 2 | M16: =K16*L16 -> 0.012 | N16: =IF(O16>0,VLOOKUP($C16,数据1!$B:$N,5,FALSE),0) -> 0.006 | O16: 2 | P16: =N16*O16 -> 0.012 | Q16: =IF(R16>0,VLOOKUP($C16,数据1!$B:$N,5,FALSE),0) -> 0.006 | R16: 2 | S16: =Q16*R16 -> 0.012
B17: 分支线设施故障 | C17: S2 | D17: =VLOOKUP(C17,数据1!B:I,3,FALSE) -> 隔离开关 | E17: =IF(F17>0,VLOOKUP(C17,数据1!B:I,5,FALSE),0) -> 0 | F17: 0 | G17: =E17*F17 -> 0 | H17: =IF(I17>0,VLOOKUP($C17,数据1!$B:$N,5,FALSE),0) -> 0.0025 | I17: 1.3 | J17: =H17*I17 -> 0.00325 | K17: =IF(L17>0,VLOOKUP($C17,数据1!$B:$N,5,FALSE),0) -> 0.0025 | L17: 2.5 | M17: =K17*L17 -> 0.00625 | N17: =IF(O17>0,VLOOKUP($C17,数据1!$B:$N,5,FALSE),0) -> 0.0025 | O17: 2.5 | P17: =N17*O17 -> 0.00625 | Q17: =IF(R17>0,VLOOKUP($C17,数据1!$B:$N,5,FALSE),0) -> 0.0025 | R17: 2.5 | S17: =Q17*R17 -> 0.00625
C18: CB2 | D18: =VLOOKUP(C18,数据1!B:I,3,FALSE) -> 断路器 | E18: =IF(F18>0,VLOOKUP(C18,数据1!B:I,5,FALSE),0) -> 0.0025 | F18: 3 | G18: =E18*F18 -> 0.0075 | H18: =IF(I18>0,VLOOKUP(C18,数据1!B:I,5,FALSE),0) -> 0.0025 | I18: 1.3 | J18: =H18*I18 -> 0.00325 | K18: =IF(L18>0,VLOOKUP($C18,数据1!$B:$N,5,FALSE),0) -> 0.0025 | L18: 1.3 | M18: =K18*L18 -> 0.00325 | N18: =IF(O18>0,VLOOKUP($C18,数据1!$B:$N,5,FALSE),0) -> 0.0025 | O18: 1.3 | P18: =N18*O18 -> 0.00325 | Q18: =IF(R18>0,VLOOKUP($C18,数据1!$B:$N,5,FALSE),0) -> 0.0025 | R18: 1.3 | S18: =Q18*R18 -> 0.00325
C19: 2—a | D19: =VLOOKUP(C19,数据1!B:I,3,FALSE) -> 电缆 | E19: =IF(F19>0,VLOOKUP(C19,数据1!B:I,5,FALSE),0) -> 0.001 | F19: 5 | G19: =E19*F19 -> 0.005 | H19: =IF(I19>0,VLOOKUP(C19,数据1!B:I,5,FALSE),0) -> 0 | I19: 0 | J19: =H19*I19 -> 0 | K19: =IF(L19>0,VLOOKUP($C19,数据1!$B:$N,5,FALSE),0) -> 0 | L19: 0 | M19: =K19*L19 -> 0 | N19: =IF(O19>0,VLOOKUP($C19,数据1!$B:$N,5,FALSE),0) -> 0 | O19: 0 | P19: =N19*O19 -> 0 | Q19: =IF(R19>0,VLOOKUP($C19,数据1!$B:$N,5,FALSE),0) -> 0 | R19: 0 | S19: =Q19*R19 -> 0
C20: 4—b | D20: =VLOOKUP(C20,数据1!B:I,3,FALSE) -> 架空线 | E20: =IF(F20>0,VLOOKUP(C20,数据1!B:I,5,FALSE),0) -> 0 | F20: 0 | G20: =E20*F20 -> 0 | H20: =IF(I20>0,VLOOKUP(C20,数据1!B:I,5,FALSE),0) -> 0.0045 | I20: 2 | J20: =H20*I20 -> 0.009 | K20: =IF(L20>0,VLOOKUP($C20,数据1!$B:$N,5,FALSE),0) -> 0.0045 | L20: 1.5 | M20: =K20*L20 -> 0.00675 | N20: =IF(O20>0,VLOOKUP($C20,数据1!$B:$N,5,FALSE),0) -> 0.0045 | O20: 1.5 | P20: =N20*O20 -> 0.00675 | Q20: =IF(R20>0,VLOOKUP($C20,数据1!$B:$N,5,FALSE),0) -> 0.0045 | R20: 1.5 | S20: =Q20*R20 -> 0.00675
C21: 5—8 | D21: =VLOOKUP(C21,数据1!B:I,3,FALSE) -> 架空线 | E21: =IF(F21>0,VLOOKUP(C21,数据1!B:I,5,FALSE),0) -> 0 | F21: 0 | G21: =E21*F21 -> 0 | H21: =IF(I21>0,VLOOKUP(C21,数据1!B:I,5,FALSE),0) -> 0 | I21: 0 | J21: =H21*I21 -> 0 | K21: =IF(L21>0,VLOOKUP($C21,数据1!$B:$N,5,FALSE),0) -> 0.003 | L21: 2 | M21: =K21*L21 -> 0.006 | N21: =IF(O21>0,VLOOKUP($C21,数据1!$B:$N,5,FALSE),0) -> 0.003 | O21: 2 | P21: =N21*O21 -> 0.006 | Q21: =IF(R21>0,VLOOKUP($C21,数据1!$B:$N,5,FALSE),0) -> 0 | R21: 0 | S21: =Q21*R21 -> 0
C22: 8—c | D22: =VLOOKUP(C22,数据1!B:I,3,FALSE) -> 架空线 | E22: =IF(F22>0,VLOOKUP(C22,数据1!B:I,5,FALSE),0) -> 0 | F22: 0 | G22: =E22*F22 -> 0 | H22: =IF(I22>0,VLOOKUP(C22,数据1!B:I,5,FALSE),0) -> 0 | I22: 0 | J22: =H22*I22 -> 0 | K22: =IF(L22>0,VLOOKUP($C22,数据1!$B:$N,5,FALSE),0) -> 0.0045 | L22: 2 | M22: =K22*L22 -> 0.009 | N22: =IF(O22>0,VLOOKUP($C22,数据1!$B:$N,5,FALSE),0) -> 0.0045 | O22: 1.3 | P22: =N22*O22 -> 0.00585 | Q22: =IF(R22>0,VLOOKUP($C22,数据1!$B:$N,5,FALSE),0) -> 0 | R22: 0 | S22: =Q22*R22 -> 0
C23: 8—d | D23: =VLOOKUP(C23,数据1!B:I,3,FALSE) -> 架空线 | E23: =IF(F23>0,VLOOKUP(C23,数据1!B:I,5,FALSE),0) -> 0 | F23: 0 | G23: =E23*F23 -> 0 | H23: =IF(I23>0,VLOOKUP(C23,数据1!B:I,5,FALSE),0) -> 0 | I23: 0 | J23: =H23*I23 -> 0 | K23: =IF(L23>0,VLOOKUP($C23,数据1!$B:$N,5,FALSE),0) -> 0.0015 | L23: 2 | M23: =K23*L23 -> 0.003 | N23: =IF(O23>0,VLOOKUP($C23,数据1!$B:$N,5,FALSE),0) -> 0.0015 | O23: 2 | P23: =N23*O23 -> 0.003 | Q23: =IF(R23>0,VLOOKUP($C23,数据1!$B:$N,5,FALSE),0) -> 0 | R23: 0 | S23: =Q23*R23 -> 0
C24: 6—e | D24: =VLOOKUP(C24,数据1!B:I,3,FALSE) -> 架空线 | E24: =IF(F24>0,VLOOKUP(C24,数据1!B:I,5,FALSE),0) -> 0 | F24: 0 | G24: =E24*F24 -> 0 | H24: =IF(I24>0,VLOOKUP(C24,数据1!B:I,5,FALSE),0) -> 0.003 | I24: 1.3 | J24: =H24*I24 -> 0.0039 | K24: =IF(L24>0,VLOOKUP($C24,数据1!$B:$N,5,FALSE),0) -> 0.003 | L24: 1.3 | M24: =K24*L24 -> 0.0039 | N24: =IF(O24>0,VLOOKUP($C24,数据1!$B:$N,5,FALSE),0) -> 0.003 | O24: 1.3 | P24: =N24*O24 -> 0.0039 | Q24: =IF(R24>0,VLOOKUP($C24,数据1!$B:$N,5,FALSE),0) -> 0.003 | R24: 2 | S24: =Q24*R24 -> 0.006
C25: S3 | D25: =VLOOKUP(C25,数据1!B:I,3,FALSE) -> 隔离开关 | E25: =IF(F25>0,VLOOKUP(C25,数据1!B:I,5,FALSE),0) -> 0 | F25: 0 | G25: =E25*F25 -> 0 | H25: =IF(I25>0,VLOOKUP(C25,数据1!B:I,5,FALSE),0) -> 0 | I25: 0 | J25: =H25*I25 -> 0 | K25: =IF(L25>0,VLOOKUP($C25,数据1!$B:$N,5,FALSE),0) -> 0.0025 | L25: 2.5 | M25: =K25*L25 -> 0.00625 | N25: =IF(O25>0,VLOOKUP($C25,数据1!$B:$N,5,FALSE),0) -> 0.0025 | O25: 2.5 | P25: =N25*O25 -> 0.00625 | Q25: =IF(R25>0,VLOOKUP($C25,数据1!$B:$N,5,FALSE),0) -> 0 | R25: 0 | S25: =Q25*R25 -> 0
C26: F5 | D26: =VLOOKUP(C26,数据1!B:I,3,FALSE) -> 熔断器 | E26: =IF(F26>0,VLOOKUP(C26,数据1!B:I,5,FALSE),0) -> 0 | F26: 0 | G26: =E26*F26 -> 0 | H26: =IF(I26>0,VLOOKUP(C26,数据1!B:I,5,FALSE),0) -> 0.002 | I26: 1.3 | J26: =H26*I26 -> 0.0026 | K26: =IF(L26>0,VLOOKUP($C26,数据1!$B:$N,5,FALSE),0) -> 0.002 | L26: 2 | M26: =K26*L26 -> 0.004 | N26: =IF(O26>0,VLOOKUP($C26,数据1!$B:$N,5,FALSE),0) -> 0.002 | O26: 2 | P26: =N26*O26 -> 0.004 | Q26: =IF(R26>0,VLOOKUP($C26,数据1!$B:$N,5,FALSE),0) -> 0.002 | R26: 2 | S26: =Q26*R26 -> 0.004
C27: Fa | D27: =VLOOKUP(C27,数据1!B:I,3,FALSE) -> 熔断器 | E27: =IF(F27>0,VLOOKUP(C27,数据1!B:I,5,FALSE),0) -> 0.002 | F27: 2 | G27: =E27*F27 -> 0.004 | H27: =IF(I27>0,VLOOKUP(C27,数据1!B:I,5,FALSE),0) -> 0 | I27: 0 | J27: =H27*I27 -> 0 | K27: =IF(L27>0,VLOOKUP($C27,数据1!$B:$N,5,FALSE),0) -> 0 | L27: 0 | M27: =K27*L27 -> 0 | N27: =IF(O27>0,VLOOKUP($C27,数据1!$B:$N,5,FALSE),0) -> 0 | O27: 0 | P27: =N27*O27 -> 0 | Q27: =IF(R27>0,VLOOKUP($C27,数据1!$B:$N,5,FALSE),0) -> 0 | R27: 0 | S27: =Q27*R27 -> 0
C28: Fb | D28: =VLOOKUP(C28,数据1!B:I,3,FALSE) -> 熔断器 | E28: =IF(F28>0,VLOOKUP(C28,数据1!B:I,5,FALSE),0) -> 0 | F28: 0 | G28: =E28*F28 -> 0 | H28: =IF(I28>0,VLOOKUP(C28,数据1!B:I,5,FALSE),0) -> 0.002 | I28: 2 | J28: =H28*I28 -> 0.004 | K28: =IF(L28>0,VLOOKUP($C28,数据1!$B:$N,5,FALSE),0) -> 0.002 | L28: 1.5 | M28: =K28*L28 -> 0.003 | N28: =IF(O28>0,VLOOKUP($C28,数据1!$B:$N,5,FALSE),0) -> 0.002 | O28: 1.5 | P28: =N28*O28 -> 0.003 | Q28: =IF(R28>0,VLOOKUP($C28,数据1!$B:$N,5,FALSE),0) -> 0.002 | R28: 1.5 | S28: =Q28*R28 -> 0.003
C29: Fc | D29: =VLOOKUP(C29,数据1!B:I,3,FALSE) -> 熔断器 | E29: =IF(F29>0,VLOOKUP(C29,数据1!B:I,5,FALSE),0) -> 0 | F29: 0 | G29: =E29*F29 -> 0 | H29: =IF(I29>0,VLOOKUP(C29,数据1!B:I,5,FALSE),0) -> 0 | I29: 0 | J29: =H29*I29 -> 0 | K29: =IF(L29>0,VLOOKUP($C29,数据1!$B:$N,5,FALSE),0) -> 0.002 | L29: 2 | M29: =K29*L29 -> 0.004 | N29: =IF(O29>0,VLOOKUP($C29,数据1!$B:$N,5,FALSE),0) -> 0.002 | O29: 1.3 | P29: =N29*O29 -> 0.0026 | Q29: =IF(R29>0,VLOOKUP($C29,数据1!$B:$N,5,FALSE),0) -> 0 | R29: 0 | S29: =Q29*R29 -> 0
... C36: Te | D36: =VLOOKUP(C36,数据1!B:I,3,FALSE) -> 变压器 | E36: =IF(F36>0,VLOOKUP(C36,数据1!B:I,5,FALSE),0) -> 0 | F36: 0 | G36: =E36*F36 -> 0 | H36: =IF(I36>0,VLOOKUP(C36,数据1!B:I,5,FALSE),0) -> 0 | I36: 0 | J36: =H36*I36 -> 0 | K36: =IF(L36>0,VLOOKUP($C36,数据1!$B:$N,5,FALSE),0) -> 0 | L36: 0 | M36: =K36*L36 -> 0 | N36: =IF(O36>0,VLOOKUP($C36,数据1!$B:$N,5,FALSE),0) -> 0 | O36: 0 | P36: =N36*O36 -> 0 | Q36: =IF(R36>0,VLOOKUP($C36,数据1!$B:$N,5,FALSE),0) -> 0.0035 | R36: 4 | S36: =Q36*R36 -> 0.014
B37: 故障 | C37: 小计 | E37: =SUM(E6:E36) -> 0.02 | F37: =G37/E37 -> 2.325 | G37: =SUM(G6:G36) -> 0.0465 | H37: =SUM(H6:H36) -> 0.0585 | I37: =J37/H37 -> 1.7461538 | J37: =SUM(J6:J36) -> 0.10215 | K37: =SUM(K6:K36) -> 0.074 | L37: =M37/K37 -> 1.8277027 | M37: =SUM(M6:M36) -> 0.13525 | N37: =SUM(N6:N36) -> 0.074 | O37: =P37/N37 -> 1.7662162 | P37: =SUM(P6:P36) -> 0.1307 | Q37: =SUM(Q6:Q36) -> 0.0585 | R37: =S37/Q37 -> 1.8205128 | S37: =SUM(S6:S36) -> 0.1065
B38: 预安排停运 | C38: 0—1 | D38: =VLOOKUP(C38,数据1!B:I,3,FALSE) -> 架空线 | E38: =IF(F38>0,VLOOKUP($C38,数据1!$B:$N,11,FALSE),0) -> 0.03 | F38: 0.2 | G38: =E38*F38 -> 0.006 | H38: =IF(I38>0,VLOOKUP($C38,数据1!$B:$N,11,FALSE),0) -> 0.03 | I38: 0.2 | J38: =H38*I38 -> 0.006 | K38: =IF(L38>0,VLOOKUP($C38,数据1!$B:$N,11,FALSE),0) -> 0.03 | L38: 0.2 | M38: =K38*L38 -> 0.006 | N38: =IF(O38>0,VLOOKUP($C38,数据1!$B:$N,11,FALSE),0) -> 0.03 | O38: 0.2 | P38: =N38*O38 -> 0.006 | Q38: =IF(R38>0,VLOOKUP($C38,数据1!$B:$N,11,FALSE),0) -> 0.03 | R38: 0.2 | S38: =Q38*R38 -> 0.006
C39: 1—2 | D39: =VLOOKUP(C39,数据1!B:I,3,FALSE) -> 电缆 | E39: =IF(F39>0,VLOOKUP($C39,数据1!$B:$N,11,FALSE),0) -> 0.12 | F39: 0.2 | G39: =E39*F39 -> 0.024 | H39: =IF(I39>0,VLOOKUP($C39,数据1!$B:$N,11,FALSE),0) -> 0.12 | I39: 0.2 | J39: =H39*I39 -> 0.024 | K39: =IF(L39>0,VLOOKUP($C39,数据1!$B:$N,11,FALSE),0) -> 0.12 | L39: 0.2 | M39: =K39*L39 -> 0.024 | N39: =IF(O39>0,VLOOKUP($C39,数据1!$B:$N,11,FALSE),0) -> 0.12 | O39: 0.2 | P39: =N39*O39 -> 0.024 | Q39: =IF(R39>0,VLOOKUP($C39,数据1!$B:$N,11,FALSE),0) -> 0.12 | R39: 0.2 | S39: =Q39*R39 -> 0.024
C40: 2—3 | D40: =VLOOKUP(C40,数据1!B:I,3,FALSE) -> 电缆 | E40: =IF(F40>0,VLOOKUP($C40,数据1!$B:$N,11,FALSE),0) -> 0 | F40: 0 | G40: =E40*F40 -> 0 | H40: =IF(I40>0,VLOOKUP($C40,数据1!$B:$N,11,FALSE),0) -> 0.18 | I40: 0.2 | J40: =H40*I40 -> 0.036 | K40: =IF(L40>0,VLOOKUP($C40,数据1!$B:$N,11,FALSE),0) -> 0.18 | L40: 0.2 | M40: =K40*L40 -> 0.036 | N40: =IF(O40>0,VLOOKUP($C40,数据1!$B:$N,11,FALSE),0) -> 0.18 | O40: 0.2 | P40: =N40*O40 -> 0.036 | Q40: =IF(R40>0,VLOOKUP($C40,数据1!$B:$N,11,FALSE),0) -> 0.18 | R40: 0.2 | S40: =Q40*R40 -> 0.036
C41: 3—4 | D41: =VLOOKUP(C41,数据1!B:I,3,FALSE) -> 架空线 | E41: =IF(F41>0,VLOOKUP($C41,数据1!$B:$N,11,FALSE),0) -> 0 | F41: 0 | G41: =E41*F41 -> 0 | H41: =IF(I41>0,VLOOKUP($C41,数据1!$B:$N,11,FALSE),0) -> 0.18 | I41: 7 | J41: =H41*I41 -> 1.26 | K41: =IF(L41>0,VLOOKUP($C41,数据1!$B:$N,11,FALSE),0) -> 0.18 | L41: 0.2 | M41: =K41*L41 -> 0.036 | N41: =IF(O41>0,VLOOKUP($C41,数据1!$B:$N,11,FALSE),0) -> 0.18 | O41: 0.2 | P41: =N41*O41 -> 0.036 | Q41: =IF(R41>0,VLOOKUP($C41,数据1!$B:$N,11,FALSE),0) -> 0.18 | R41: 0.2 | S41: =Q41*R41 -> 0.036
C42: 4—5 | D42: =VLOOKUP(C42,数据1!B:I,3,FALSE) -> 架空线 | E42: =IF(F42>0,VLOOKUP($C42,数据1!$B:$N,11,FALSE),0) -> 0 | F42: 0 | G42: =E42*F42 -> 0 | H42: =IF(I42>0,VLOOKUP($C42,数据1!$B:$N,11,FALSE),0) -> 0 | I42: 0 | J42: =H42*I42 -> 0 | K42: =IF(L42>0,VLOOKUP($C42,数据1!$B:$N,11,FALSE),0) -> 0.06 | L42: 7 | M42: =K42*L42 -> 0.42 | N42: =IF(O42>0,VLOOKUP($C42,数据1!$B:$N,11,FALSE),0) -> 0.06 | O42: 7 | P42: =N42*O42 -> 0.42 | Q42: =IF(R42>0,VLOOKUP($C42,数据1!$B:$N,11,FALSE),0) -> 0.06 | R42: 7 | S42: =Q42*R42 -> 0.42
C43: 5—6 | D43: =VLOOKUP(C43,数据1!B:I,3,FALSE) -> 架空线 | E43: =IF(F43>0,VLOOKUP($C43,数据1!$B:$N,11,FALSE),0) -> 0 | F43: 0 | G43: =E43*F43 -> 0 | H43: =IF(I43>0,VLOOKUP($C43,数据1!$B:$N,11,FALSE),0) -> 0 | I43: 0 | J43: =H43*I43 -> 0 | K43: =IF(L43>0,VLOOKUP($C43,数据1!$B:$N,11,FALSE),0) -> 0.12 | L43: 7 | M43: =K43*L43 -> 0.84 | N43: =IF(O43>0,VLOOKUP($C43,数据1!$B:$N,11,FALSE),0) -> 0.12 | O43: 7 | P43: =N43*O43 -> 0.84 | Q43: =IF(R43>0,VLOOKUP($C43,数据1!$B:$N,11,FALSE),0) -> 0.12 | R43: 7 | S43: =Q43*R43 -> 0.84
C44: 5—8 | D44: =VLOOKUP(C44,数据1!B:I,3,FALSE) -> 架空线 | E44: =IF(F44>0,VLOOKUP($C44,数据1!$B:$N,11,FALSE),0) -> 0 | F44: 0 | G44: =E44*F44 -> 0 | H44: =IF(I44>0,VLOOKUP($C44,数据1!$B:$N,11,FALSE),0) -> 0 | I44: 0 | J44: =H44*I44 -> 0 | K44: =IF(L44>0,VLOOKUP($C44,数据1!$B:$N,11,FALSE),0) -> 0.06 | L44: 7 | M44: =K44*L44 -> 0.42 | N44: =IF(O44>0,VLOOKUP($C44,数据1!$B:$N,11,FALSE),0) -> 0.06 | O44: 7 | P44: =N44*O44 -> 0.42 | Q44: =IF(R44>0,VLOOKUP($C44,数据1!$B:$N,11,FALSE),0) -> 0 | R44: 0 | S44: =Q44*R44 -> 0
C45: 2—a | D45: =VLOOKUP(C45,数据1!B:I,3,FALSE) -> 电缆 | E45: =IF(F45>0,VLOOKUP($C45,数据1!$B:$N,11,FALSE),0) -> 0.06 | F45: 7 | G45: =E45*F45 -> 0.42 | H45: =IF(I45>0,VLOOKUP($C45,数据1!$B:$N,11,FALSE),0) -> 0 | I45: 0 | J45: =H45*I45 -> 0 | K45: =IF(L45>0,VLOOKUP($C45,数据1!$B:$N,11,FALSE),0) -> 0 | L45: 0 | M45: =K45*L45 -> 0 | N45: =IF(O45>0,VLOOKUP($C45,数据1!$B:$N,11,FALSE),0) -> 0 | O45: 0 | P45: =N45*O45 -> 0 | Q45: =IF(R45>0,VLOOKUP($C45,数据1!$B:$N,11,FALSE),0) -> 0 | R45: 0 | S45: =Q45*R45 -> 0
C46: 4—b | D46: =VLOOKUP(C46,数据1!B:I,3,FALSE) -> 架空线 | E46: =IF(F46>0,VLOOKUP($C46,数据1!$B:$N,11,FALSE),0) -> 0 | F46: 0 | G46: =E46*F46 -> 0 | H46: =IF(I46>0,VLOOKUP($C46,数据1!$B:$N,11,FALSE),0) -> 0.09 | I46: 7 | J46: =H46*I46 -> 0.63 | K46: =IF(L46>0,VLOOKUP($C46,数据1!$B:$N,11,FALSE),0) -> 0.09 | L46: 0.2 | M46: =K46*L46 -> 0.018 | N46: =IF(O46>0,VLOOKUP($C46,数据1!$B:$N,11,FALSE),0) -> 0.09 | O46: 0.2 | P46: =N46*O46 -> 0.018 | Q46: =IF(R46>0,VLOOKUP($C46,数据1!$B:$N,11,FALSE),0) -> 0.09 | R46: 0.2 | S46: =Q46*R46 -> 0.018
C47: 8—c | D47: =VLOOKUP(C47,数据1!B:I,3,FALSE) -> 架空线 | E47: =IF(F47>0,VLOOKUP($C47,数据1!$B:$N,11,FALSE),0) -> 0 | F47: 0 | G47: =E47*F47 -> 0 | H47: =IF(I47>0,VLOOKUP($C47,数据1!$B:$N,11,FALSE),0) -> 0 | I47: 0 | J47: =H47*I47 -> 0 | K47: =IF(L47>0,VLOOKUP($C47,数据1!$B:$N,11,FALSE),0) -> 0.09 | L47: 7 | M47: =K47*L47 -> 0.63 | N47: =IF(O47>0,VLOOKUP($C47,数据1!$B:$N,11,FALSE),0) -> 0.09 | O47: 0.2 | P47: =N47*O47 -> 0.018 | Q47: =IF(R47>0,VLOOKUP($C47,数据1!$B:$N,11,FALSE),0) -> 0 | R47: 0 | S47: =Q47*R47 -> 0
...

Sheet 可靠性指标
D1: 表C.4 负荷点可靠性指标
B2: 公式 | C2: 负荷点指标 | D2: 负荷点a | G2: 负荷点b | J2: 负荷点c | M2: 负荷点d | P2: 负荷点e
A3: （0） | C3: 户数 | D3: 1 | G3: 1 | J3: 1 | M3: 1 | P3: 1
A4: （1） | C4: 容量 | D4: 800 | G4: 200 | J4: 50 | M4: 100 | P4: 315
A5: （2） | B5: 查分析表 | C5: 负荷点停电率期望值λLP（次/年） | D5: =故障后果模式分析表!E51 -> 0.23 | G5: =故障后果模式分析表!H51 -> 0.6585 | J5: =故障后果模式分析表!K51 -> 1.094 | M5: =故障后果模式分析表!N51 -> 1.094 | P5: =故障后果模式分析表!Q51 -> 0.8985
A6: （3） | B6: 查分析表 | C6: 负荷点停电时间期望值uLP（h/年) | D6: =故障后果模式分析表!G51 -> 0.4965 | G6: =故障后果模式分析表!J51 -> 2.05815 | J6: =故障后果模式分析表!M51 -> 2.78725 | M6: =故障后果模式分析表!P51 -> 2.1707 | P6: =故障后果模式分析表!S51 -> 1.9065
A7: （4） | B7: = （6）/Σ（1） | C7: 负荷点等效系统停电小时数SIEH-LP (h/年) | D7: =D9/SUM($D4:$P4) -> 0.27112628 | G7: =G9/SUM($D4:$P4) -> 0.28097611 | J7: =J9/SUM($D4:$P4) -> 0.095127986 | M7: =M9/SUM($D4:$P4) -> 0.14817065 | P7: =P9/SUM($D4:$P4) -> 0.40993174
A8: （5） | B8: = 1-（3）/8760 | C8: 负荷点平均供电可用率ASAI-LP | D8: 0.99994 | G8: 0.99977 | J8: 0.99968 | M8: 0.99975 | P8: 0.99978
A9: （6） | B9: =（1）*（3） | C9: 负荷点缺供电量ENS-LP(kWh/年) | D9: 397.2 | G9: 411.63 | J9: 139.3625 | M9: 217.07 | P9: 600.55
C13: 表C.5 系统可靠性指标
C14: 系统指标 | D14: 指标值 | J14: 计算值
A15: （7） | B15: = Σ[（0）*（2）]/Σ（0） | C15: 系统平均停电频率期望值SAIFI（次/户•年） | D15: 0.795 | J15: =(D5*D3+G5*G3+J5*J3+M5*M3+P5*P3)/SUM(D3:P3) -> 0.795
A16: （8） | B16: = Σ[（0）*（3）]/Σ（0） | C16: 系统平均停电时间期望值SAIDI（h/户•年) | D16: 1.88382 | J16: =(D6*D3+G6*G3+J6*J3+M6*M3+P6*P3)/SUM(D3:P3) -> 1.88382
A17: （9） | B17: = 1-（8）/8760 | C17: 平均供电可用率期望值ASAI | D17: 0.99978 | J17: =1-J16/8760 -> 0.99978495
A18: （10） | B18: = Σ（6） | C18: 系统缺供电量期望值ENS（kWh） | D18: 1765.81 | J18: =SUM(D9:P9) -> 1765.8125
A19: （11） | B19: = Σ（6）/Σ（0） | C19: 系统平均缺供电量期望值AENS( kWh/户•年) | D19: 353.162 | J19: =J18/SUM(D3:P3) -> 353.1625
